Workbook

Sheet All
A1: Assets | B1: Liabilities | C1: Expenses/Losses | D1: Revenues/Gains | E1: Stockholders Equity
A2: Accounts Receivable | B2: Accounts Payable | C2: Accounting Fees | D2: Advertising Earnings | E2: Accumulated Other Comprehenseive Income
A3: Accumulated Depletion | B3: Accrued Interest | C3: Advertising Fees | D3: Commission Receipts | E3: Accumulated Profits
A4: Accumulated Depreciation | B4: Accrued Rent | C4: Amortization Costs | D4: Dividend Earnings | E4: Additional Paid in Capital - Common Stock
A5: Advances to Officers, Directors, and Employees | B5: Accrued Salaries | C5: Artist Fees | D5: Foreign Exchange Gains | E5: Additional Paid in Capital - Preferred Stock
A6: Allowance for Doubtful Accounts | B6: Accrued Utilities | C6: Attorney Fees | D6: Gain on Disposal of Property, Plant, & Equipment | E6: Additional Paid in Capital - Treasury Stock
A7: Allowance to Adjust Available-for-Sale Securities to Market | B7: Bonds Payable | C7: Bad Debts | D7: Gain on Sale of Intangibles | E7: Common Stock
A8: Allowance to Adjust Trading Securities to Market | B8: Capital Lease Liability | C8: Bank Service Charges | D8: Gain on Sale of Investments | E8: Dividends Paid
A9: Buildings | B9: Charitable Contributions Payable | C9: Bookkeeping Costs | D9: Gain on Settlement of Lawsuit | E9: Preferred Stock
A10: Cash | B10: Commissions Payable | C10: Cash Over and Short | D10: Grant Receipts | E10: Retained Earnings
A11: Cash Equivalents | B11: Credit Card Payable | C11: Charitable Contributions Costs | D11: Interest Earnings | E11: Treasury Stock
A12: Certificates of Deposit | B12: Customer Deposits | C12: Commissions Costs | D12: Investment lncome - Equity Method | E12: Unrealized Gain on Available for Sale Securities
A13: Checking Accounts | B13: Customer Refunds Payable | C13: Consulting Fees | D13: Membership & Subscription Earnings | E13: Unrealized Loss on Available for Sale Securities
A14: Computer Equipment | B14: Deferred Income Tax Liability | C14: Cost of Goods Sold | D14: Rent Receipts
A15: Computer Hardware | B15: Discount on Bonds Payable | C15: Cost of Sales | D15: Royalty Income
A16: Copyright | B16: Discount on Notes Payable | C16: Delivery Fees | D16: Sales
A17: Customer Lists | B17: Dividends Payable | C17: Depreciation Costs | D17: Sales Discounts
A18: Deferred Tax Assets | B18: Excise Taxes Payable | C18: Electricity Fees | D18: Sales Returns and Allowances
A19: Equipment | B19: Federal Income Tax Withholdings Payable | C19: Entertainment Costs | D19: Unrealized Gain on Trading Securities
A20: Finished Goods Inventory | B20: Federal Unemployment Taxes Payable | C20: Equipment Rental Fees
A21: Franchise | B21: FICA Taxes Payable | C21: Federal Taxes Paid
A22: Furniture | B22: Fines Payable | C22: Fines and Penalties
A23: Goodwill | B23: Income Taxes Payable | C23: Foreign Exchange Losses
A24: Interest Receivable | B24: Insurance Payable | C24: Gas Costs
A25: Inventory | B25: Interest Payable | C25: Income Taxes Costs
A26: Investment in Subsidiary | B26: Lawsuit Payable | C26: Insurance Costs
A27: Investments | B27: Lease Liability | C27: Interest Costs
A28: Investments-Available-for-Sale Securities | B28: Legal Fees Payable | C28: IT Costs
A29: Investments-Equity Method | B29: Line of Credit Payable | C29: Legal Fees
A30: Investments-Trading Securities | B30: Loans Payable | C30: License Fees and Taxes
A31: Land | B31: Medicare Taxes Payable | C31: Loss from Impairment
... A58: Trucks | B58: Warranty Liability | C58: Store Supplies Costs
A59: Work-in-Process Inventory | C59: Supplies Costs
C60: Taxes Costs
C61: Trade Show Costs
C62: Training Costs
C63: Transportation-In
C64: Travel Costs
C65: Unemployment Taxes Costs
C66: Utilities Fees
...

Sheet All - Tutorial
A1: Assets | B1: Liabilities | C1: Expenses/Losses | D1: Revenues/Gains | E1: Stockholders Equity
A2: =_xlfn.CONCAT(All!A2, " - Assets") -> Accounts Receivable - Assets | B2: =_xlfn.CONCAT(All!B2, " - Liabilities") -> Accounts Payable - Liabilities | C2: =_xlfn.CONCAT(All!C3, " - Expense") -> Advertising Fees - Expense | D2: =_xlfn.CONCAT(All!D2, " - Revenue") -> Advertising Earnings - Revenue | E2: =_xlfn.CONCAT(All!E2, " - Stockholder's Equity") -> Accumulated Other Comprehenseive Income - Stockholder's Equity
A3: =_xlfn.CONCAT(All!A3, " - Assets") -> Accumulated Depletion - Assets | B3: =_xlfn.CONCAT(All!B3, " - Liabilities") -> Accrued Interest - Liabilities | C3: =_xlfn.CONCAT(All!C2, " - Expense") -> Accounting Fees - Expense | D3: =_xlfn.CONCAT(All!D3, " - Revenue") -> Commission Receipts - Revenue | E3: =_xlfn.CONCAT(All!E3, " - Stockholder's Equity") -> Accumulated Profits - Stockholder's Equity
A4: =_xlfn.CONCAT(All!A4, " - Assets") -> Accumulated Depreciation - Assets | B4: =_xlfn.CONCAT(All!B4, " - Liabilities") -> Accrued Rent - Liabilities | C4: =_xlfn.CONCAT(All!C4, " - Expense") -> Amortization Costs - Expense | D4: =_xlfn.CONCAT(All!D4, " - Revenue") -> Dividend Earnings - Revenue | E4: =_xlfn.CONCAT(All!E4, " - Stockholder's Equity") -> Additional Paid in Capital - Common Stock - Stockholder's Equity
A5: =_xlfn.CONCAT(All!A5, " - Assets") -> Advances to Officers, Directors, and Employees - Assets | B5: =_xlfn.CONCAT(All!B5, " - Liabilities") -> Accrued Salaries - Liabilities | C5: =_xlfn.CONCAT(All!C5, " - Expense") -> Artist Fees - Expense | D5: =_xlfn.CONCAT(All!D5, " - Revenue") -> Foreign Exchange Gains - Revenue | E5: =_xlfn.CONCAT(All!E5, " - Stockholder's Equity") -> Additional Paid in Capital - Preferred Stock - Stockholder's Equity
A6: =_xlfn.CONCAT(All!A6, " - Assets") -> Allowance for Doubtful Accounts - Assets | B6: =_xlfn.CONCAT(All!B6, " - Liabilities") -> Accrued Utilities - Liabilities | C6: =_xlfn.CONCAT(All!C6, " - Expense") -> Attorney Fees - Expense | D6: =_xlfn.CONCAT(All!D6, " - Revenue") -> Gain on Disposal of Property, Plant, & Equipment - Revenue | E6: =_xlfn.CONCAT(All!E6, " - Stockholder's Equity") -> Additional Paid in Capital - Treasury Stock - Stockholder's Equity
A7: =_xlfn.CONCAT(All!A7, " - Assets") -> Allowance to Adjust Available-for-Sale Securities to Market - Assets | B7: =_xlfn.CONCAT(All!B7, " - Liabilities") -> Bonds Payable - Liabilities | C7: =_xlfn.CONCAT(All!C7, " - Expense") -> Bad Debts - Expense | D7: =_xlfn.CONCAT(All!D7, " - Revenue") -> Gain on Sale of Intangibles - Revenue | E7: =_xlfn.CONCAT(All!E7, " - Stockholder's Equity") -> Common Stock - Stockholder's Equity
A8: =_xlfn.CONCAT(All!A8, " - Assets") -> Allowance to Adjust Trading Securities to Market - Assets | B8: =_xlfn.CONCAT(All!B8, " - Liabilities") -> Capital Lease Liability - Liabilities | C8: =_xlfn.CONCAT(All!C8, " - Expense") -> Bank Service Charges - Expense | D8: =_xlfn.CONCAT(All!D8, " - Revenue") -> Gain on Sale of Investments - Revenue | E8: =_xlfn.CONCAT(All!E8, " - Stockholder's Equity") -> Dividends Paid - Stockholder's Equity
A9: =_xlfn.CONCAT(All!A9, " - Assets") -> Buildings - Assets | B9: =_xlfn.CONCAT(All!B9, " - Liabilities") -> Charitable Contributions Payable - Liabilities | C9: =_xlfn.CONCAT(All!C9, " - Expense") -> Bookkeeping Costs - Expense | D9: =_xlfn.CONCAT(All!D9, " - Revenue") -> Gain on Settlement of Lawsuit - Revenue | E9: =_xlfn.CONCAT(All!E9, " - Stockholder's Equity") -> Preferred Stock - Stockholder's Equity
A10: =_xlfn.CONCAT(All!A10, " - Assets") -> Cash - Assets | B10: =_xlfn.CONCAT(All!B10, " - Liabilities") -> Commissions Payable - Liabilities | C10: =_xlfn.CONCAT(All!C66, " - Expense") -> Utilities Fees - Expense | D10: =_xlfn.CONCAT(All!D10, " - Revenue") -> Grant Receipts - Revenue | E10: =_xlfn.CONCAT(All!E10, " - Stockholder's Equity") -> Retained Earnings - Stockholder's Equity
A11: =_xlfn.CONCAT(All!A11, " - Assets") -> Cash Equivalents - Assets | B11: =_xlfn.CONCAT(All!B11, " - Liabilities") -> Credit Card Payable - Liabilities | C11: =_xlfn.CONCAT(All!C10, " - Expense") -> Cash Over and Short - Expense | D11: =_xlfn.CONCAT(All!D11, " - Revenue") -> Interest Earnings - Revenue | E11: =_xlfn.CONCAT(All!E11, " - Stockholder's Equity") -> Treasury Stock - Stockholder's Equity
A12: =_xlfn.CONCAT(All!A12, " - Assets") -> Certificates of Deposit - Assets | B12: =_xlfn.CONCAT(All!B12, " - Liabilities") -> Customer Deposits - Liabilities | C12: =_xlfn.CONCAT(All!C11, " - Expense") -> Charitable Contributions Costs - Expense | D12: =_xlfn.CONCAT(All!D12, " - Revenue") -> Investment lncome - Equity Method - Revenue | E12: =_xlfn.CONCAT(All!E12, " - Stockholder's Equity") -> Unrealized Gain on Available for Sale Securities - Stockholder's Equity
A13: =_xlfn.CONCAT(All!A13, " - Assets") -> Checking Accounts - Assets | B13: =_xlfn.CONCAT(All!B13, " - Liabilities") -> Customer Refunds Payable - Liabilities | C13: =_xlfn.CONCAT(All!C12, " - Expense") -> Commissions Costs - Expense | D13: =_xlfn.CONCAT(All!D13, " - Revenue") -> Membership & Subscription Earnings - Revenue | E13: =_xlfn.CONCAT(All!E13, " - Stockholder's Equity") -> Unrealized Loss on Available for Sale Securities - Stockholder's Equity
A14: =_xlfn.CONCAT(All!A14, " - Assets") -> Computer Equipment - Assets | B14: =_xlfn.CONCAT(All!B14, " - Liabilities") -> Deferred Income Tax Liability - Liabilities | C14: =_xlfn.CONCAT(All!C13, " - Expense") -> Consulting Fees - Expense | D14: =_xlfn.CONCAT(All!D14, " - Revenue") -> Rent Receipts - Revenue
A15: =_xlfn.CONCAT(All!A15, " - Assets") -> Computer Hardware - Assets | B15: =_xlfn.CONCAT(All!B15, " - Liabilities") -> Discount on Bonds Payable - Liabilities | C15: =_xlfn.CONCAT(All!C14, " - Expense") -> Cost of Goods Sold - Expense | D15: =_xlfn.CONCAT(All!D15, " - Revenue") -> Royalty Income - Revenue
A16: =_xlfn.CONCAT(All!A16, " - Assets") -> Copyright - Assets | B16: =_xlfn.CONCAT(All!B16, " - Liabilities") -> Discount on Notes Payable - Liabilities | C16: =_xlfn.CONCAT(All!C15, " - Expense") -> Cost of Sales - Expense | D16: =_xlfn.CONCAT(All!D16, " - Revenue") -> Sales - Revenue
A17: =_xlfn.CONCAT(All!A17, " - Assets") -> Customer Lists - Assets | B17: =_xlfn.CONCAT(All!B17, " - Liabilities") -> Dividends Payable - Liabilities | C17: =_xlfn.CONCAT(All!C16, " - Expense") -> Delivery Fees - Expense | D17: =_xlfn.CONCAT(All!D17, " - Revenue") -> Sales Discounts - Revenue
A18: =_xlfn.CONCAT(All!A18, " - Assets") -> Deferred Tax Assets - Assets | B18: =_xlfn.CONCAT(All!B18, " - Liabilities") -> Excise Taxes Payable - Liabilities | C18: =_xlfn.CONCAT(All!C17, " - Expense") -> Depreciation Costs - Expense | D18: =_xlfn.CONCAT(All!D18, " - Revenue") -> Sales Returns and Allowances - Revenue
A19: =_xlfn.CONCAT(All!A19, " - Assets") -> Equipment - Assets | B19: =_xlfn.CONCAT(All!B56, " - Liabilities") -> Utilities Payable - Liabilities | C19: =_xlfn.CONCAT(All!C18, " - Expense") -> Electricity Fees - Expense | D19: =_xlfn.CONCAT(All!D19, " - Revenue") -> Unrealized Gain on Trading Securities - Revenue
A20: =_xlfn.CONCAT(All!A20, " - Assets") -> Finished Goods Inventory - Assets | B20: =_xlfn.CONCAT(All!B57, " - Liabilities") -> Wages Payable - Liabilities | C20: =_xlfn.CONCAT(All!C19, " - Expense") -> Entertainment Costs - Expense
A21: =_xlfn.CONCAT(All!A21, " - Assets") -> Franchise - Assets | B21: =_xlfn.CONCAT(All!B19, " - Liabilities") -> Federal Income Tax Withholdings Payable - Liabilities | C21: =_xlfn.CONCAT(All!C67, " - Expense") -> Wages Costs - Expense
A22: =_xlfn.CONCAT(All!A22, " - Assets") -> Furniture - Assets | B22: =_xlfn.CONCAT(All!B20, " - Liabilities") -> Federal Unemployment Taxes Payable - Liabilities | C22: =_xlfn.CONCAT(All!C20, " - Expense") -> Equipment Rental Fees - Expense
A23: =_xlfn.CONCAT(All!A23, " - Assets") -> Goodwill - Assets | B23: =_xlfn.CONCAT(All!B21, " - Liabilities") -> FICA Taxes Payable - Liabilities | C23: =_xlfn.CONCAT(All!C21, " - Expense") -> Federal Taxes Paid - Expense
A24: =_xlfn.CONCAT(All!A24, " - Assets") -> Interest Receivable - Assets | B24: =_xlfn.CONCAT(All!B22, " - Liabilities") -> Fines Payable - Liabilities | C24: =_xlfn.CONCAT(All!C22, " - Expense") -> Fines and Penalties - Expense
A25: =_xlfn.CONCAT(All!A25, " - Assets") -> Inventory - Assets | B25: =_xlfn.CONCAT(All!B23, " - Liabilities") -> Income Taxes Payable - Liabilities | C25: =_xlfn.CONCAT(All!C23, " - Expense") -> Foreign Exchange Losses - Expense
A26: =_xlfn.CONCAT(All!A26, " - Assets") -> Investment in Subsidiary - Assets | B26: =_xlfn.CONCAT(All!B24, " - Liabilities") -> Insurance Payable - Liabilities | C26: =_xlfn.CONCAT(All!C24, " - Expense") -> Gas Costs - Expense
A27: =_xlfn.CONCAT(All!A27, " - Assets") -> Investments - Assets | B27: =_xlfn.CONCAT(All!B25, " - Liabilities") -> Interest Payable - Liabilities | C27: =_xlfn.CONCAT(All!C25, " - Expense") -> Income Taxes Costs - Expense
A28: =_xlfn.CONCAT(All!A28, " - Assets") -> Investments-Available-for-Sale Securities - Assets | B28: =_xlfn.CONCAT(All!B26, " - Liabilities") -> Lawsuit Payable - Liabilities | C28: =_xlfn.CONCAT(All!C26, " - Expense") -> Insurance Costs - Expense
A29: =_xlfn.CONCAT(All!A29, " - Assets") -> Investments-Equity Method - Assets | B29: =_xlfn.CONCAT(All!B27, " - Liabilities") -> Lease Liability - Liabilities | C29: =_xlfn.CONCAT(All!C27, " - Expense") -> Interest Costs - Expense
A30: =_xlfn.CONCAT(All!A30, " - Assets") -> Investments-Trading Securities - Assets | B30: =_xlfn.CONCAT(All!B28, " - Liabilities") -> Legal Fees Payable - Liabilities | C30: =_xlfn.CONCAT(All!C28, " - Expense") -> IT Costs - Expense
A31: =_xlfn.CONCAT(All!A31, " - Assets") -> Land - Assets | B31: =_xlfn.CONCAT(All!B29, " - Liabilities") -> Line of Credit Payable - Liabilities | C31: =_xlfn.CONCAT(All!C29, " - Expense") -> Legal Fees - Expense
A32: =_xlfn.CONCAT(All!A32, " - Assets") -> Leased Assets - Assets | B32: =_xlfn.CONCAT(All!B30, " - Liabilities") -> Loans Payable - Liabilities | C32: =_xlfn.CONCAT(All!C30, " - Expense") -> License Fees and Taxes - Expense
A33: =_xlfn.CONCAT(All!A33, " - Assets") -> Leasehold Improvements - Assets | B33: =_xlfn.CONCAT(All!B31, " - Liabilities") -> Medicare Taxes Payable - Liabilities | C33: =_xlfn.CONCAT(All!C31, " - Expense") -> Loss from Impairment - Expense
... A44: =_xlfn.CONCAT(All!A44, " - Assets") -> Prepaid Rent - Assets | B44: =_xlfn.CONCAT(All!B42, " - Liabilities") -> Royalties Payable - Liabilities | C44: =_xlfn.CONCAT(All!C42, " - Expense") -> Postage Costs - Expense
A45: =_xlfn.CONCAT(All!#REF!, " - Assets") -> #REF! | B45: =_xlfn.CONCAT(All!B43, " - Liabilities") -> Salaries Payable - Liabilities | C45: =_xlfn.CONCAT(All!C68, " - Expense") -> Warranty Costs - Expense
A46: =_xlfn.CONCAT(All!A45, " - Assets") -> Prepaid Repairs & Maintenance - Assets | B46: =_xlfn.CONCAT(All!B44, " - Liabilities") -> Sales Taxes Payable - Liabilities | C46: =_xlfn.CONCAT(All!C43, " - Expense") -> Promotional Materials Costs - Expense
A47: =_xlfn.CONCAT(All!A46, " - Assets") -> Prepaid Security Services - Assets | B47: =_xlfn.CONCAT(All!B58, " - Liabilities") -> Warranty Liability - Liabilities | C47: =_xlfn.CONCAT(All!C69, " - Expense") -> Water Fees - Expense
A48: =_xlfn.CONCAT(All!A47, " - Assets") -> Prepaid Subscriptions - Assets | B48: =_xlfn.CONCAT(All!B45, " - Liabilities") -> Short-Term Notes Payable - Liabilities | C48: =_xlfn.CONCAT(All!C44, " - Expense") -> Property Tax Fees - Expense
A49: =_xlfn.CONCAT(All!A48, " - Assets") -> Raw Materials Inventory - Assets | B49: =_xlfn.CONCAT(All!B46, " - Liabilities") -> Social Security Taxes Payable - Liabilities | C49: =_xlfn.CONCAT(All!C45, " - Expense") -> Purchase Allowances - Expense
A50: =_xlfn.CONCAT(All!A49, " - Assets") -> Rent Receivable - Assets | B50: =_xlfn.CONCAT(All!B47, " - Liabilities") -> State Unemployment Taxes Payable - Liabilities | C50: =_xlfn.CONCAT(All!C46, " - Expense") -> Purchases - Expense
...

Sheet BS Easy
A1: Assets | B1: Liabilities | C1: Stockholders Equity
A2: Accounts Receivable | B2: Accounts Payable | C2: Common Stock
A3: Cash | B3: Credit Card Payable | C3: Dividends Paid
A4: Buildings | B4: Bonds Payable | C4: Retained Earnings
A5: Cash Equivalents | B5: Fines Payable
A6: Cash on Hand | B6: Insurance Payable
A7: Computer Equipment | B7: Interest Payable
A8: Equipment | B8: Legal Fees Payable
A9: Furniture | B9: Line of Credit Payable
A10: Goodwill | B10: Loans Payable
A11: Interest Receivable | B11: Mortgage Payable
A12: Inventory | B12: Notes Payable
A13: Investments | B13: Payroll Taxes Payable
A14: Land | B14: Rent Payable
A15: Leasehold Improvements | B15: Repair & Maintenance Payable
A16: Notes Receivable | B16: Salaries Payable
... A19: Prepaid Advertising | B19: Utilities Payable
A20: Prepaid Insurance
A21: Prepaid Office Supplies
A22: Prepaid Rent
A23: Prepaid Rent
A24: Prepaid Repairs & Maintenance
A25: Prepaid Security Services
A26: Prepaid Subscriptions
A27: Rent Receivable
A28: Trucks

Sheet BS Medium
A1: Assets | B1: Liabilities | C1: Stockholders Equity
A2: Accounts Receivable | B2: Accounts Payable | C2: Accumulated Profits
A3: Accumulated Depletion | B3: Accrued Interest | C3: Additional Paid in Capital - Common Stock
A4: Accumulated Depreciation | B4: Accrued Rent | C4: Additional Paid in Capital - Preferred Stock
A5: Allowance for Doubtful Accounts | B5: Accrued Salaries | C5: Additional Paid in Capital - Treasury Stock
A6: Buildings | B6: Accrued Utilities | C6: Common Stock
A7: Cash | B7: Bonds Payable | C7: Dividends Paid
A8: Checking Accounts | B8: Charitable Contributions Payable | C8: Preferred Stock
A9: Computer Hardware | B9: Commissions Payable | C9: Retained Earnings
A10: Copyright | B10: Customer Deposits | C10: Treasury Stock
A11: Customer Lists | B11: Customer Refunds Payable
A12: Equipment | B12: Dividends Payable
A13: Finished Goods Inventory | B13: Excise Taxes Payable
A14: Franchise | B14: Federal Income Tax Withholdings Payable
A15: Goodwill | B15: Federal Unemployment Taxes Payable
A16: Interest Receivable | B16: FICA Taxes Payable
A17: Inventory | B17: Income Taxes Payable
A18: Investments | B18: Interest Payable
A19: Land | B19: Lawsuit Payable
A20: Leased Assets | B20: Lease Liability
A21: Money Market Accounts | B21: Loans Payable
A22: Notes Receivable | B22: Medicare Taxes Payable
... A34: Work-in-Process Inventory | B34: Unearned Sales Revenue
B35: Unearned Service Revenue
B36: Unemployment Taxes Payable
B37: Union Dues Payable
B38: Wages Payable
B39: Warranty Liability

Sheet BS Hard
A1: Assets | B1: Liabilities | C1: Stockholders Equity
A2: Accounts Receivable | B2: Accounts Payable | C2: Accumulated Other Comprehenseive Income
A3: Accumulated Depletion | B3: Accrued Interest | C3: Accumulated Profits
A4: Accumulated Depreciation | B4: Accrued Rent | C4: Additional Paid in Capital - Common Stock
A5: Advances to Officers, Directors, and Employees | B5: Bonds Payable | C5: Additional Paid in Capital - Preferred Stock
A6: Allowance for Doubtful Accounts | B6: Capital Lease Liability | C6: Additional Paid in Capital - Treasury Stock
A7: Allowance to Adjust Available-for-Sale Securities to Market | B7: Credit Card Payable | C7: Common Stock
A8: Allowance to Adjust Trading Securities to Market | B8: Customer Deposits | C8: Dividends Paid
A9: Buildings | B9: Customer Refunds Payable | C9: Preferred Stock
A10: Cash | B10: Deferred Income Tax Liability | C10: Retained Earnings
A11: Certificates of Deposit | B11: Discount on Bonds Payable | C11: Treasury Stock
A12: Copyright | B12: Discount on Notes Payable | C12: Unrealized Gain on Available for Sale Securities
A13: Customer Lists | B13: Income Taxes Payable | C13: Unrealized Loss on Available for Sale Securities
A14: Deferred Tax Assets | B14: Interest Payable
A15: Franchise | B15: Lease Liability
A16: Goodwill | B16: Leased Assets
A17: Interest Receivable | B17: Line of Credit Payable
A18: Investment in Subsidiary | B18: Loans Payable
A19: Investments | B19: Medicare Taxes Payable
A20: Investments-Available-for-Sale Securities | B20: Mortgage Payable
A21: Investments-Equity Method | B21: Notes Payable
A22: Investments-Trading Securities | B22: Premium on Bonds Payable
A23: Marketable Securities | B23: Premium on Notes Payable
A24: Natural Resources | B24: Property Taxes Payable
A25: Notes Receivable | B25: Provision for Lawsuit
... A35: Treasury Bills | B35: Utilities Payable
B36: Warranty Liability

Sheet IS Easy
A1: Expenses/Losses | B1: Revenues/Gains
A2: Accounting Costs | B2: Dividend Income
A3: Advertising Costs | B3: Interest Income
A4: Bank Service Charges | B4: Rent Income
A5: Bookkeeping Costs | B5: Sales
A6: Charitable Contributions Costs | B6: Service Income
A7: Electricity Fees
A8: Entertainment Costs
A9: Federal Taxes Paid
A10: Fines
A11: Gas Costs
A12: Insurance Costs
A13: Interest Costs
A14: Legal Fees
A15: Meals Costs
A16: Miscellaneous Costs
A17: Postage Fees
A18: Repairs & Maintenance Costs
... A28: Water Fees

Sheet IS Medium
A1: Expenses/Losses | B1: Revenues/Gains
A2: Advertising Costs | B2: Advertising Income
A3: Accounting Costs | B3: Commission Received
A4: Amortization Costs | B4: Dividend Income
A5: Artist Fees | B5: Gain on Disposal of Property, Plant, & Equipment
A6: Attorney Fees | B6: Gain on Sale of Intangibles
A7: Bad Debts | B7: Gain on Sale of Investments
A8: Commissions Paid | B8: Gain on Settlement of Lawsuit
A9: Consulting Fees | B9: Interest Income
A10: Cost of Goods Sold | B10: Membership & Subscription Income
A11: Cost of Sales | B11: Rent Income
A12: Delivery Fees | B12: Sales
... A15: Income Taxes Paid | B15: Service Income
A16: Insurance Costs
A17: Interest Costs
A18: IT Fees
A19: Licensing Fees and Taxes
A20: Loss on Disposal of Property,Plant, & Equipment
A21: Loss on Sale of Intangibles
A22: Loss on Sale of Investments
A23: Medicare Taxes Paid
A24: Office Rent Fees
A25: Penalties and Fines
A26: Promotional Materials Costs
A27: Property Taxes Paid
... A43: Utilities Fees

Sheet IS Hard
A1: Expenses/Losses | B1: Revenues/Gains
A2: Loss on Sale of Investments | B2: Advertising Income
A3: Accounting Costs | B3: Commissions Received
A4: Advertising Costs | B4: Dividend Income
A5: Amortization Costs | B5: Foreign Exchange Gains
A6: Attorney Fees | B6: Gain on Disposal of Property, Plant, & Equipment
A7: Bad Debts | B7: Gain on Sale of Intangibles
A8: Cash Over and Short | B8: Gain on Sale of Investments
A9: Commissions Paid | B9: Gain on Settlement of Lawsuit
A10: Consulting Fees | B10: Grants Received
A11: Cost of Goods Sold | B11: Interest Income
A12: Cost of Sales | B12: Investment lncome - Equity Method
... A20: Loss from Impairment | B20: Unrealized Gain on Trading Securities
A21: Loss on Disposal of Property,Plant, & Equipment
A22: Loss on Sale of Intangibles
A23: Meals Costs
A24: Medicare Taxes Paid
A25: Organizational Costs
A26: Purchases
A27: Purchases Allowances
A28: Purchases Discounts
A29: Rent Fees
A30: Repairs & Maintenance Costs
A31: Research and Development Costs
A32: Royalties Costs
... A39: Utilities Fees

Sheet Normal Balance - All
A1: Debits | B1: Credits
A2: Accounting Expense | B2: Accounts Payable
A3: Accounts Receivable | B3: Bonds Payable
A4: Advertising Expense | B4: Common Stock
A5: Bank Service Charge Expense | B5: Credit Card Payable
A6: Bookkeeping Expense | B6: Dividend Income
A7: Buildings | B7: Fines Payable
A8: Cash | B8: Insurance Payable
A9: Cash Equivalents | B9: Interest Income
A10: Cash on Hand | B10: Interest Payable
A11: Charitable Contributions Expense | B11: Legal Fees Payable
A12: Computer Equipment | B12: Line of Credit Payable
... A92: Savings Accounts | B92: Unrealized Gain on Trading Securities
A93: Security Services Expense
A94: Service Charge Expense
A95: Service Equipment
A96: Short-Term Bonds Receivable
A97: Social Security Taxes Expense
A98: Software Subscription Expense
A99: Supplies Inventory
A100: Trade Show Expense
A101: Trademark
A102: Training Expense
A103: Treasury Stock
A104: Unemployment Taxes Expense
... A127: Unrealized Loss on Available for Sale Securities

Sheet Normal Balance Easy
A1: Debits | B1: Credits
A2: Accounting Expense | B2: Accounts Payable
A3: Accounts Receivable | B3: Bonds Payable
A4: Advertising Expense | B4: Common Stock
A5: Bank Service Charge Expense | B5: Credit Card Payable
A6: Bookkeeping Expense | B6: Dividend Income
A7: Buildings | B7: Fines Payable
A8: Cash | B8: Insurance Payable
A9: Cash Equivalents | B9: Interest Income
A10: Cash on Hand | B10: Interest Payable
A11: Charitable Contributions Expense | B11: Legal Fees Payable
A12: Computer Equipment | B12: Line of Credit Payable
... A30: Miscellaneous Expense | B30: Utilities Payable
A31: Notes Receivable
A32: Office Equipment
A33: Other Assets
A34: Other Expense
A35: Patents
A36: Postage Expense
A37: Prepaid Advertising
A38: Prepaid Insurance
A39: Prepaid Office Supplies
A40: Prepaid Rent
A41: Prepaid Rent
A42: Prepaid Repairs & Maintenance
... A57: Water Expense

Sheet Normal Balance Medium
A1: Debit | B1: Credit
A2: Accounting Expense | B2: Accounts Payable
A3: Accounts Receivable | B3: Accrued Interest
A4: Advertising Expense | B4: Accrued Rent
A5: Amortization Expense | B5: Accrued Salaries
A6: Artist Fee Expense | B6: Accrued Utilities
A7: Attorney Fees | B7: Accumulated Depletion
A8: Bad Debt Expense | B8: Accumulated Depreciation
A9: Buildings | B9: Accumulated Profits
A10: Cash | B10: Additional Paid in Capital - Common Stock
A11: Checking Accounts | B11: Additional Paid in Capital - Preferred Stock
A12: Commissions Expense | B12: Additional Paid in Capital - Treasury Stock
... A65: Software Subscription Expense | B65: Warranty Liability
A66: Supplies Expense
A67: Supplies Inventory
A68: Taxes Expense
A69: Trade Show Expense
A70: Trademark
A71: Training Expense
A72: Travel Expense
A73: Treasury Stock
A74: Unemployment Taxes Expense
A75: Utilities Expense
A76: Work-in-Process Inventory

Sheet Normal Balance Hard
A1: Debit | B1: Credit
A2: Bad Debt Expense | B2: Accounts Payable
A3: Franchise | B3: Accrued Interest
A4: Foreign Exchange Losses | B4: Accrued Rent
A5: Accounting Expense | B5: Accumulated Depletion
A6: Accounts Receivable | B6: Accumulated Depreciation
A7: Natural Resources | B7: Accumulated Profits
A8: Loss on Disposal of Property,Plant, & Equipment | B8: Additional Paid in Capital - Common Stock
A9: Loss on Sale of Intangibles | B9: Additional Paid in Capital - Preferred Stock
A10: Loss on Sale of Investments | B10: Additional Paid in Capital - Treasury Stock
A11: Taxes Expense | B11: Advertising Revenue
A12: Accumulated Other Comprehenseive Income | B12: Allowance for Doubtful Accounts
... A69: Equipment Rental Expense | B69: Warranty Liability
A70: Treasury Bills
A71: Treasury Stock
A72: Unrealized Loss on Available for Sale Securities
A73: Utilities Expense

Sheet A=L+SE - Easy
C3: A= | D3: L+ | E3: SE | G3: Answer a | H3: Answer b | I3: Answer c | J3: Answer d | K3: Solution
B4: 1 | C4: 500 | D4: 200 | E4: 300 | F4: Aubie Co. has $500 in equipment and a $200 note payable. What is Aubie Co's equity? | G4: 200 | H4: 300 | I4: 500 | J4: 700 | K4: 300
B5: 2 | C5: 1500 | D5: 1000 | E5: 500 | F5: Tigers Unlimited has a $1,000 mortgage and $500 of equity associated with a piece of land. What is the book value of the land? | G5: 500 | H5: 1000 | I5: 1500 | J5: 2000 | K5: 1500
B6: 3 | C6: 900 | D6: 500 | E6: 400 | F6: The book value of a truck is $900 and equity is $400. How much is the associated liability? | G6: 400 | H6: 500 | I6: 900 | J6: 1300 | K6: 500
B7: 4 | C7: 1200 | D7: 700 | E7: 500 | F7: XYZ Company owns a building worth $1,200 and owes $700 on it. What is the owner's equity? | G7: 500 | H7: 800 | I7: 1200 | J7: 1900 | K7: 500
B8: 5 | C8: 750 | D8: 250 | E8: 500 | F8: If equipment is worth $750 and liabilities total $250, what is the equity in the equipment? | G8: 250 | H8: 500 | I8: 750 | J8: 1000 | K8: 500
B9: 6 | C9: 1800 | D9: 1200 | E9: 600 | F9: A factory is valued at $1,800. If liabilities are $1,200, what is the owner's equity? | G9: 600 | H9: 1200 | I9: 1800 | J9: 3000 | K9: 600
B10: 7 | C10: 1000 | D10: 400 | E10: 600 | F10: ABC Company has assets of $1,000 and equity of $600. What is the amount of liabilities? | G10: 400 | H10: 600 | I10: 1000 | J10: 1600 | K10: 400
B11: 8 | C11: 2200 | D11: 800 | E11: 1400 | F11: Land is valued at $2,200, with $800 owed. What is the company’s equity in the land? | G11: 800 | H11: 1400 | I11: 2200 | J11: 3000 | K11: 1400
B12: 9 | C12: 1600 | D12: 1100 | E12: 500 | F12: AM Partnership has $1,600 in assets and $1,100 in liabilities. What is its equity? | G12: 500 | H12: 1100 | I12: 1600 | J12: 2700 | K12: 500
B13: 10 | C13: 1300 | D13: 300 | E13: 1000 | F13: If equity in a patent is $1,000 and liabilities are $300, what is the asset’s value? | G13: 300 | H13: 700 | I13: 1000 | J13: 1300 | K13: 1300
B14: 11 | C14: 600 | D14: 100 | E14: 500 | F14: A laptop has a book value of $600 and equity of $500. What is the liability amount? | G14: 100 | H14: 500 | I14: 600 | J14: 1100 | K14: 100
B15: 12 | C15: 2000 | D15: 1500 | E15: 500 | F15: If total assets are $2,000 and liabilities are $1,500, how much is the equity? | G15: 500 | H15: 1500 | I15: 2000 | J15: 3500 | K15: 500
... B23: 20 | C23: 1500 | D23: 1250 | E23: 250 | F23: Samford Inc. has $1,500 in a couch and equity of $250, how much does Samford Inc. have in liabilities? | G23: 250 | H23: 1250 | I23: 1500 | J23: 1750 | K23: 1250
A26: Key to question 1 | B26: a | C26: 200 | D26: c | E26: 500
B27: b | C27: 300 | D27: d | E27: 700

Sheet A=L+SE - Medium
C2: Elements
B3: Transaction # | C3: A= | D3: L+ | E3: SE | F3: (Net Income) | G3: Transaction Description | I3: Wrong 1 | J3: Wrong 2
B4: 1 | C4: + | E4: + | F4: + | G4: Aubie Co. sells 500 widgets on credit. What is the impact on the equation? | I4: A: - L: + SE: NI:
B5: 2 | C5: + | D5: + | G5: AM Partnership purchases equipment using a note payable. What is the effect?
B6: 3 | C6: + | E6: + | F6: + | G6: Tigers Unlimited performs consulting work on account. What is the impact?
B7: 4 | C7: – | E7: – | G7: War Eagle Inc. pays cash dividends to shareholders. How does this affect the equation? | I7: 13-15 | J7: effect
B8: 5 | C8: – | E8: – | F8: – | G8: Office supplies worth $300 are used up and expensed. What is the effect? | I8: 5-7 | J8: impact
B9: 6 | C9: + | E9: + | F9: + | G9: Revenue of $1,000 is earned and collected in cash. What is the effect? | I9: get rid of "On..."
B10: 7 | C10: + | D10: + | G10: New computers are bought on account. What is the impact?
B11: 8 | C11: – | E11: – | F11: – | G11: Salaries expense of $700 is paid. What is the effect on the equation?
B12: 9 | C12: + | D12: + | G12: Andy purchases a $500 bond from Tigers Unlimited. What is the impact on Tigers' books?
B13: 10 | C13: + | E13: + | G13: Mallory purchases 1,000 shares of common stock in Aubie Co. What is the effect?
B14: 11 | C14: – | D14: – | G14: Lowder Inc pays off a loan using cash. How does this impact the equation?
B15: 12 | C15: + | D15: + | G15: Inventory is purchased on account. What is the effect?
B16: 13 | C16: – | E16: – | F16: – | G16: Rent is paid for the month. How is the equation affected?
B17: 14 | D17: + | E17: – | F17: – | G17: Harbert LLC incurs an expense on account. What is the effect?
B18: 15 | C18: – | E18: – | F18: – | G18: Depreciation is recorded on equipment. What is the effect?
B19: 16 | C19: – | E19: + | F19: + | G19: Turner Corp. sells an automobile for cash. What is the effect?
B20: 17 | C20: + | E20: + | F20: + | G20: J&M Bookstore sells 500 sweatshirts at a profit. What is the impact?
B21: 18 | C21: – | E21: – | F21: – | G21: Toomers Drugs pays interest on a loan. What is the impact?
B22: 19 | G22: Samford Inc. purchases 1,000 t-shirts for resale with cash. What is the effect on the equation?
B23: 20 | C23: + | D23: + | G23: Orange and Navy LLP takes out a loan and uses this loan to purchase a building. What is the effect?

Sheet A=L+SE - Hard
C2: Elements
B3: Transaction # | C3: A= | D3: L+ | E3: SE | F3: (Net Income) | G3: Transaction Description - What is the resulting impact on the financial statements?
B4: 1 | C4: O | D4: NE | E4: O | F4: O | G4: Aubie Co purchased a 1-year insurance policy on June 1 of Year 1 and failed to make an adjustment at year-end.
B5: 2 | C5: U | D5: U | E5: NE | F5: NE | G5: AM Partnership received loan proceeds on July 1st and did not make a journal entry.
B6: 3 | C6: NE | D6: NE | E6: NE | F6: NE | G6: Tigers Unlimited collected $500 from a customer for an outstanding account. The cash collection was not recorded.
B7: 4 | C7: O | D7: NE | E7: O | F7: O | G7: Supplies purchased earlier were used during the period, but no adjusting entry was made to recognize supplies expense.
B8: 5 | C8: U | D8: NE | E8: U | F8: U | G8: Revenue paid and\ earned in December was not recorded until January.
B9: 6 | C9: O | D9: NE | E9: O | F9: O | G9: Depreciation expense was omitted at year-end.
B10: 7 | C10: NE | D10: U | E10: O | F10: O | G10: Wages earned (but not paid) in December were not recorded until January.
B11: 8 | C11: U | D11: NE | E11: U | F11: NE | G11: Harbert Inc failed to record the sale of common stock for cash.
B12: 9 | C12: NE | D12: U | E12: U | F12: U | G12: Lowder LLC did not accrue utilities expense at year-end.
B13: 10 | C13: O | D13: O | E13: NE | F13: NE | G13: War Eagle Co failed to record repayment of a note payable.
B14: 11 | C14: U | D14: U | E14: NE | F14: NE | G14: Orange and Navy Inc. forgot to record a loan that they took out and received cash for the loan.
B15: 12 | C15: O | D15: NE | E15: U | F15: U | G15: Turner Corp. sold an automobile at a gain but did not record the transaction
... B23: 20 | C23: O | D23: NE | E23: O | F23: O | G23: Jordan-Hare LLP forgets to record the transaction for payment of utilities. It was paid for with cash.
